<?xml version="1.0" encoding="utf-8"?>
<robot name="panda">
  <material name="panda_white">
    <color rgba="1 1 1 1"/>
  </material>
  <material name="panda_gray">
    <color rgba="0.4 0.4 0.4 1"/>
  </material>
  <material name="silver">
    <color rgba="0.5 0.5 0.5 1"/>
  </material>
  <link name="panda_link0">
    <visual>
      <geometry>
        <mesh filename="meshes/visual/link0.dae"/>
      </geometry>
      <material name="panda_gray"/>
    </visual>
    <collision>
      <geometry>
        <mesh filename="meshes/collision/link0.stl"/>
      </geometry>
    </collision>
  </link>
  <link name="panda_link1">
    <visual>
      <geometry>
        <mesh filename="meshes/visual/link1.dae"/>
      </geometry>
      <material name="panda_white"/>
    </visual>
    <collision>
      <geometry>
        <mesh filename="meshes/collision/link1.stl"/>
      </geometry>
    </collision>
    <inertial>
      <origin rpy="0 0 0" xyz="3.875e-03 2.081e-03 -0.1750"/>
      <mass value="4.970684"/>
      <inertia ixx="7.0337e-01" ixy="-1.3900e-04" ixz="6.7720e-03" iyy="7.0661e-01" iyz="1.9169e-02" izz="9.1170e-03"/>
    </inertial>
  </link>
  <joint name="panda_joint1" type="revolute">
    <safety_controller k_position="100.0" k_velocity="40.0" soft_lower_limit="-2.8973" soft_upper_limit="2.8973"/>
    <origin rpy="0 0 0" xyz="0 0 0.333"/>
    <parent link="panda_link0"/>
    <child link="panda_link1"/>
    <axis xyz="0 0 1"/>
    <limit effort="87" lower="-2.8973" upper="2.8973" velocity="2.1750"/>
    <dynamics damping="10.0" friction="5.0"/>
  </joint>
  <link name="panda_link2">
    <visual>
      <geometry>
        <mesh filename="meshes/visual/link2.dae"/>
      </geometry>
      <material name="panda_white"/>
    </visual>
    <collision>
      <geometry>
        <mesh filename="meshes/collision/link2.stl"/>
      </geometry>
    </collision>
    <inertial>
      <origin rpy="0 0 0" xyz="-3.141e-03 -2.872e-02 3.495e-03"/>
      <mass value="0.646926"/>
      <inertia ixx="7.9620e-03" ixy="-3.9250e-03" ixz="1.0254e-02" iyy="2.8110e-02" iyz="7.0400e-04" izz="2.5995e-02"/>
    </inertial>
  </link>
  <joint name="panda_joint2" type="revolute">
    <safety_controller k_position="100.0" k_velocity="40.0" soft_lower_limit="-1.7628" soft_upper_limit="1.7628"/>
    <origin rpy="-1.57079632679 0 0" xyz="0 0 0"/>
    <parent link="panda_link1"/>
    <child link="panda_link2"/>
    <axis xyz="0 0 1"/>
    <limit effort="87" lower="-1.7628" upper="1.7628" velocity="2.1750"/>
    <dynamics damping="5.0" friction="2.0"/>
  </joint>
  <link name="panda_link3">
    <visual>
      <geometry>
        <mesh filename="meshes/visual/link3.dae"/>
      </geometry>
      <material name="panda_white"/>
    </visual>
    <collision>
      <geometry>
        <mesh filename="meshes/collision/link3.stl"/>
      </geometry>
    </collision>
    <inertial>
      <origin rpy="0 0 0" xyz="2.7518e-02 3.9252e-02 -6.6502e-02"/>
      <mass value="3.228604"/>
      <inertia ixx="3.7242e-02" ixy="-4.7610e-03" ixz="-1.1396e-02" iyy="3.6155e-02" iyz="-1.2805e-02" izz="1.0830e-02"/>
    </inertial>
  </link>
  <joint name="panda_joint3" type="revolute">
    <safety_controller k_position="100.0" k_velocity="40.0" soft_lower_limit="-2.8973" soft_upper_limit="2.8973"/>
    <origin rpy="1.57079632679 0 0" xyz="0 -0.316 0"/>
    <parent link="panda_link2"/>
    <child link="panda_link3"/>
    <axis xyz="0 0 1"/>
    <limit effort="87" lower="-2.8973" upper="2.8973" velocity="2.1750"/>
    <dynamics damping="5.0" friction="2.0"/>
  </joint>
  <link name="panda_link4">
    <visual>
      <geometry>
        <mesh filename="meshes/visual/link4.dae"/>
      </geometry>
      <material name="panda_white"/>
    </visual>
    <collision>
      <geometry>
        <mesh filename="meshes/collision/link4.stl"/>
      </geometry>
    </collision>
    <inertial>
      <origin rpy="0 0 0" xyz="-5.317e-02 1.04419e-01 2.7454e-02"/>
      <mass value="3.587895"/>
      <inertia ixx="2.5853e-02" ixy="7.7960e-03" ixz="-1.3320e-03" iyy="1.9552e-02" iyz="8.6410e-03" izz="2.8323e-02"/>
    </inertial>
  </link>
  <joint name="panda_joint4" type="revolute">
    <safety_controller k_position="100.0" k_velocity="40.0" soft_lower_limit="-3.0718" soft_upper_limit="-0.0698"/>
    <origin rpy="1.57079632679 0 0" xyz="0.0825 0 0"/>
    <parent link="panda_link3"/>
    <child link="panda_link4"/>
    <axis xyz="0 0 1"/>
    <limit effort="87" lower="-3.0718" upper="-0.0698" velocity="2.1750"/>
    <dynamics damping="1.0" friction="0.5"/>
  </joint>
  <link name="panda_link5">
    <visual>
      <geometry>
        <mesh filename="meshes/visual/link5.dae"/>
      </geometry>
      <material name="panda_white"/>
    </visual>
    <collision>
      <geometry>
        <mesh filename="meshes/collision/link5.stl"/>
      </geometry>
    </collision>
    <inertial>
      <origin rpy="0 0 0" xyz="-1.1953e-02 4.1065e-02 -3.8437e-02"/>
      <mass value="1.225946"/>
      <inertia ixx="3.5549e-02" ixy="-2.1170e-03" ixz="-4.0370e-03" iyy="2.9474e-02" iyz="2.2900e-04" izz="8.6270e-03"/>
    </inertial>
  </link>
  <joint name="panda_joint5" type="revolute">
    <safety_controller k_position="100.0" k_velocity="40.0" soft_lower_limit="-2.8973" soft_upper_limit="2.8973"/>
    <origin rpy="-1.57079632679 0 0" xyz="-0.0825 0.384 0"/>
    <parent link="panda_link4"/>
    <child link="panda_link5"/>
    <axis xyz="0 0 1"/>
    <limit effort="12" lower="-2.8973" upper="2.8973" velocity="2.6100"/>
    <dynamics damping="2.0" friction="1.0"/>
  </joint>
  <link name="panda_link6">
    <visual>
      <geometry>
        <mesh filename="meshes/visual/link6.dae"/>
      </geometry>
      <material name="panda_white"/>
    </visual>
    <collision>
      <geometry>
        <mesh filename="meshes/collision/link6.stl"/>
      </geometry>
    </collision>
    <inertial>
      <origin rpy="0 0 0" xyz="6.0149e-02 -1.4117e-02 -1.0517e-02"/>
      <mass value="1.666555"/>
      <inertia ixx="1.9640e-03" ixy="1.0900e-04" ixz="-1.1580e-03" iyy="4.3540e-03" iyz="3.4100e-04" izz="5.4330e-03"/>
    </inertial>
  </link>
  <joint name="panda_joint6" type="revolute">
    <safety_controller k_position="100.0" k_velocity="40.0" soft_lower_limit="-0.0175" soft_upper_limit="3.7525"/>
    <origin rpy="1.57079632679 0 0" xyz="0 0 0"/>
    <parent link="panda_link5"/>
    <child link="panda_link6"/>
    <axis xyz="0 0 1"/>
    <limit effort="12" lower="-0.0175" upper="3.7525" velocity="2.6100"/>
    <dynamics damping="1.0" friction="0.5"/>
  </joint>
  <link name="panda_link7">
    <visual>
      <geometry>
        <mesh filename="meshes/visual/link7.dae"/>
      </geometry>
      <material name="panda_gray"/>
    </visual>
    <collision>
      <geometry>
        <mesh filename="meshes/collision/link7.stl"/>
      </geometry>
    </collision>
    <inertial>
      <origin rpy="0 0 0" xyz="1.0517e-02 -4.252e-03 6.1597e-02"/>
      <mass value="7.35522e-01"/>
      <inertia ixx="1.2516e-02" ixy="-4.2800e-04" ixz="-1.1960e-03" iyy="1.0027e-02" iyz="-7.4100e-04" izz="4.8150e-03"/>
    </inertial>
  </link>
  <joint name="panda_joint7" type="revolute">
    <safety_controller k_position="100.0" k_velocity="40.0" soft_lower_limit="-2.8973" soft_upper_limit="2.8973"/>
    <origin rpy="1.57079632679 0 0" xyz="0.088 0 0"/>
    <parent link="panda_link6"/>
    <child link="panda_link7"/>
    <axis xyz="0 0 1"/>
    <limit effort="12" lower="-2.8973" upper="2.8973" velocity="2.6100"/>
    <dynamics damping="1.0" friction="0.5"/>
  </joint>
  <link name="panda_link8">
    <inertial>
      <origin rpy="0 0 0" xyz="0 0 0"/>
      <mass value="0.0"/>
      <inertia ixx="0.001" ixy="0.0" ixz="0.0" iyy="0.001" iyz="0.0" izz="0.001"/>
    </inertial>
  </link>
  <joint name="panda_joint8" type="fixed">
    <origin rpy="0 0 0" xyz="0 0 0.107"/>
    <parent link="panda_link7"/>
    <child link="panda_link8"/>
    <axis xyz="0 0 0"/>
  </joint>
  <link name="wrist_connector">
    <visual>
      <origin rpy="0 0 0" xyz="0 0 0"/>
      <geometry>
        <mesh scale="0.001 0.001 0.001" filename="meshes/visual/connector.stl"/>
      </geometry>
      <material name="panda_white"/>
    </visual>
  </link>
  <joint name="arm_to_connector" type="fixed">
    <origin xyz="0 0 0.008" rpy="1.57 0 1.57"/>
    <parent link="panda_link8"/>
    <child link="wrist_connector"/>
    <axis xyz="0 0 0"/>
  </joint>
  <link name="wrist">
    <inertial>
      <mass value="0.400"/>
      <inertia ixx="978.26e-6" ixy="87.34e-6" ixz="322.99e-6" iyy="1244.78e-6" iyz="244.74e-6" izz="456.22e-6"/>
      <origin xyz="22.41911e-3 -0.15798201e-3 -0.01319866e-3" rpy="0 0 0"/>
    </inertial>
    <!--WristPlateBone-->
    <visual>
      <origin xyz="27.412417e-3 -0.454432e-3 26.510489e-3" rpy="0.006361 -0.088345 3.069623"/>
      <geometry>
        <cylinder length="3.9e-3" radius="24.05e-3"/>
      </geometry>
    </visual>
    <!--Wrist Bone 2-->
    <visual>
      <origin xyz="36.796220e-3 -8.001000e-3 12.124025e-3" rpy="-3.086612 -0.059956 2.398653"/>
      <geometry>
        <cylinder length="25.000660e-3" radius="3.500000e-3"/>
      </geometry>
    </visual>
    <!--Wrist Bone-->
    <visual>
      <origin xyz="8.509640e-3 -8.001000e-3 14.636040e-3" rpy="-0.059614 0.065548 -0.738965"/>
      <geometry>
        <cylinder length="25.000001e-3" radius="3.500000e-3"/>
      </geometry>
    </visual>
    <!--Bar Bone-->
    <visual>
      <origin xyz="25.349180e-3 -8.001000e-3 0.000000e-3" rpy="1.570796 -0.785398 -1.570796"/>
      <geometry>
        <cylinder length="66.000000e-3" radius="7.00000e-3"/>
      </geometry>
    </visual>
    <!--Pinky Bone-->
    <visual>
      <origin xyz="50.889805e-3 -8.753450e-3 -29.632815e-3" rpy="-0.076208 -0.019754 -0.799369"/>
      <geometry>
        <cylinder length="67.000008e-3" radius="3.500000e-3"/>
      </geometry>
    </visual>
    <!--Ringbone Bone-->
    <visual>
      <origin xyz="31.064135e-3 -10.290505e-3 -34.034900e-3" rpy="-0.103572 -0.064539 -0.831114"/>
      <geometry>
        <cylinder length="67.000202e-3" radius="3.500000e-3"/>
      </geometry>
    </visual>
    <!--Middlebone Bone-->
    <visual>
      <origin xyz="12.268540e-3 -12.148345e-3 -34.606210e-3" rpy="-0.122139 -0.012729 -0.794400"/>
      <geometry>
        <cylinder length="67.000001e-3" radius="3.500000e-3"/>
      </geometry>
    </visual>
    <!--Index Bone-->
    <visual>
      <origin xyz="-5.830855e-3 -10.981725e-3 -33.241905e-3" rpy="-0.133914 0.042071 -0.755627"/>
      <geometry>
        <cylinder length="59.999993e-3" radius="3.500000e-3"/>
      </geometry>
    </visual>
    <visual>
      <origin rpy="0 0 0" xyz="0 0 0"/>
      <geometry>
        <mesh filename="meshes/visual/FB_palm_ref.stl"/>
      </geometry>
      <material name="panda_white"/>
    </visual>
  </link>
  <joint name="connector_to_wrist" type="fixed">
    <origin xyz="-0.024 0.076 0.005" rpy="1.57 0 -0.09"/>
    <parent link="wrist_connector"/>
    <child link="wrist"/>
    <axis xyz="0 0 0"/>
  </joint>
  <link name="index_L1">
    <inertial>
      <mass value="0.00635888"/>
      <inertia ixx="0.29766e-6" ixy="-0.06447133e-6" ixz="-0.00423315e-6" iyy="3.6947967e-6" iyz="0.00083028e-6" izz="3.8176336e-6"/>
      <origin xyz="22.41911e-3 -0.15798201e-3 -0.01319866e-3" rpy="0 0 0"/>
    </inertial>
    <visual>
      <origin xyz="0 0 0" rpy="0 0 0"/>
      <geometry>
        <!--<cylinder length="8" radius="7"/>-->
        <sphere radius="7e-3"/>
      </geometry>
    </visual>
    <visual>
      <origin xyz="19.23500e-3 1.62500e-3 0" rpy="0 0 0.084474"/>
      <geometry>
        <box size="38.6070382e-3 4e-3 4e-3"/>
      </geometry>
    </visual>
    <visual>
      <origin xyz="38.472723e-3 3.257695e-3 0.000000" rpy="0 0 0.084474"/>
      <geometry>
        <mesh filename="meshes/visual/idx-F1.stl"/>
      </geometry>
      <material name="panda_white"/>
    </visual>
  </link>
  <link name="index_L2">
    <inertial>
      <mass value="0.00645"/>
      <inertia ixx="0.82671e-6" ixy="-1.08876e-6" ixz="-0.00037e-6" iyy="1.98028e-6" iyz="0.00081e-6" izz="2.64638e-6"/>
      <origin rpy="0 0 0" xyz="13.36818e-3 -8.75392e-3 -0.02886e-3"/>
    </inertial>
    <visual>
      <origin xyz="0 0 0" rpy="0 0 0"/>
      <geometry>
        <sphere radius="5e-3"/>
      </geometry>
    </visual>
    <visual>
      <origin xyz="15.5333e-3 -8.501e-3 0" rpy="0 0 -0.500734962"/>
      <geometry>
        <box size="35.41e-3 4e-3 4e-3"/>
      </geometry>
    </visual>
    <visual>
      <origin xyz="29.159500e-3 -11.643970e-3 -0.148280e-3" rpy="1.5708 0 -0.420107"/>
      <geometry>
        <cylinder length="3e-3" radius="4e-3"/>
      </geometry>
    </visual>
    <visual>
      <origin rpy="0 0 0" xyz="9.1241e-3 0 0"/>
      <geometry>
        <mesh filename="meshes/visual/idx-F2.stl"/>
      </geometry>
      <material name="panda_white"/>
    </visual>
  </link>
  <joint name="index_q1" type="revolute">
    <parent link="wrist"/>
    <child link="index_L1"/>
    <origin xyz="-9.49e-3 -13.04e-3 -62.95e-3" rpy="-1.982050 1.284473 -2.090591"/>
    <axis xyz="0 0 1"/>
    <limit lower="0" upper="2.0943951" effort="0.20" velocity="8.0677777442"/>
    <!-- angles in rad, efforts in N-m, velocity in rad/s -->
    <dynamics damping="0.001" friction="0.001"/>
    <!-- Friction coefficient is not from quantitative measurement -->
  </joint>
  <joint name="index_q2" type="revolute">
    <parent link="index_L1"/>
    <child link="index_L2"/>
    <origin xyz="38.472723e-3 3.257695e-3 0.000000e-3" rpy="0 0 0.084474"/>
    <axis xyz="0 0 1"/>
    <limit lower="0.0" upper="2.6586" effort="0.20" velocity="8.0677777442"/>
    <!-- angles in rad, efforts in N-m, velocity in rad/s -->
    <dynamics damping="0.001" friction="0.001"/>
    <!-- Friction coefficient is not from quantitative measurement -->
  </joint>
  <link name="middle_L1">
    <inertial>
      <mass value="0.00635888"/>
      <inertia ixx="0.29766e-6" ixy="-0.06447133e-6" ixz="-0.00423315e-6" iyy="3.6947967e-6" iyz="0.00083028e-6" izz="3.8176336e-6"/>
      <origin xyz="22.41911e-3 -0.15798201e-3 -0.01319866e-3" rpy="0 0 0"/>
    </inertial>
    <visual>
      <origin xyz="0 0 0" rpy="0 0 0"/>
      <geometry>
        <!--<cylinder length="8" radius="7"/>-->
        <sphere radius="7e-3"/>
      </geometry>
    </visual>
    <visual>
      <origin xyz="19.23500e-3 1.62500e-3 0" rpy="0 0 0.084474"/>
      <geometry>
        <box size="38.6070382e-3 4e-3 4e-3"/>
      </geometry>
    </visual>
    <visual>
      <origin xyz="38.472723e-3 3.257695e-3 0.000000" rpy="0 0 0.084474"/>
      <geometry>
        <mesh filename="meshes/visual/idx-F1.stl"/>
      </geometry>
      <material name="panda_white"/>
    </visual>
  </link>
  <link name="middle_L2">
    <inertial>
      <mass value="0.00645"/>
      <inertia ixx="0.82671e-6" ixy="-1.08876e-6" ixz="-0.00037e-6" iyy="1.98028e-6" iyz="0.00081e-6" izz="2.64638e-6"/>
      <origin rpy="0 0 0" xyz="13.36818e-3 -8.75392e-3 -0.02886e-3"/>
    </inertial>
    <visual>
      <origin xyz="0 0 0" rpy="0 0 0"/>
      <geometry>
        <sphere radius="5e-3"/>
      </geometry>
    </visual>
    <visual>
      <origin xyz="15.5333e-3 -8.501e-3 0" rpy="0 0 -0.500734962"/>
      <geometry>
        <box size="35.41e-3 4e-3 4e-3"/>
      </geometry>
    </visual>
    <visual>
      <origin xyz="29.159500e-3 -11.643970e-3 -0.148280e-3" rpy="1.5708 0 -0.420107"/>
      <geometry>
        <cylinder length="3e-3" radius="4e-3"/>
      </geometry>
    </visual>
    <visual>
      <origin rpy="0 0 0" xyz="9.1241e-3 0 0"/>
      <geometry>
        <mesh filename="meshes/visual/idx-F2.stl"/>
      </geometry>
      <material name="panda_white"/>
    </visual>
  </link>
  <joint name="middle_q1" type="revolute">
    <parent link="wrist"/>
    <child link="middle_L1"/>
    <origin xyz="9.653191e-3 -15.310271e-3 -67.853949e-3" rpy="-1.860531 1.308458 -1.896217"/>
    <limit lower="0" upper="2.0943951" effort="0.20" velocity="8.0677777442"/>
    <!-- angles in rad, efforts in N-m, velocity in rad/s -->
    <dynamics damping="0.001" friction="0.001"/>
    <!-- Friction coefficient is not from quantitative measurement -->
    <axis xyz="0 0 1"/>
  </joint>
  <joint name="middle_q2" type="revolute">
    <parent link="middle_L1"/>
    <child link="middle_L2"/>
    <origin xyz="38.472723e-3 3.257695e-3 0.000000" rpy="0 0 0.084474"/>
    <axis xyz="0 0 1"/>
    <limit lower="0.0" upper="2.6586" effort="0.20" velocity="8.0677777442"/>
    <!-- angles in rad, efforts in N-m, velocity in rad/s -->
    <dynamics damping="0.001" friction="0.001"/>
    <!-- Friction coefficient is not from quantitative measurement -->
  </joint>
  <link name="ring_L1">
    <inertial>
      <mass value="0.00635888"/>
      <inertia ixx="0.29766e-6" ixy="-0.06447133e-6" ixz="-0.00423315e-6" iyy="3.6947967e-6" iyz="0.00083028e-6" izz="3.8176336e-6"/>
      <origin xyz="22.41911e-3 -0.15798201e-3 -0.01319866e-3" rpy="0 0 0"/>
    </inertial>
    <visual>
      <origin xyz="0 0 0" rpy="0 0 0"/>
      <geometry>
        <sphere radius="7e-3"/>
        <!--<cylinder length="8" radius="7"/>-->
      </geometry>
    </visual>
    <visual>
      <origin xyz="19.23500e-3 1.62500e-3 0" rpy="0 0 0.084474"/>
      <geometry>
        <box size="38.6070382e-3 4e-3 4e-3"/>
      </geometry>
    </visual>
    <visual>
      <origin xyz="38.472723e-3 3.257695e-3 0.000000" rpy="0 0 0.084474"/>
      <geometry>
        <mesh filename="meshes/visual/idx-F1.stl"/>
      </geometry>
      <material name="panda_white"/>
    </visual>
  </link>
  <link name="ring_L2">
    <inertial>
      <mass value="0.00645"/>
      <inertia ixx="0.82671e-6" ixy="-1.08876e-6" ixz="-0.00037e-6" iyy="1.98028e-6" iyz="0.00081e-6" izz="2.64638e-6"/>
      <origin rpy="0 0 0" xyz="13.36818e-3 -8.75392e-3 -0.02886e-3"/>
    </inertial>
    <visual>
      <origin xyz="0 0 0" rpy="0 0 0"/>
      <geometry>
        <sphere radius="5e-3"/>
      </geometry>
    </visual>
    <visual>
      <origin xyz="15.5333e-3 -8.501e-3 0" rpy="0 0 -0.500734962"/>
      <geometry>
        <box size="35.41e-3 4e-3 4e-3"/>
      </geometry>
    </visual>
    <visual>
      <origin xyz="29.159500e-3 -11.643970e-3 -0.148280e-3" rpy="1.5708 0 -0.420107"/>
      <geometry>
        <cylinder length="3e-3" radius="4e-3"/>
      </geometry>
    </visual>
    <visual>
      <origin rpy="0 0 0" xyz="9.1241e-3 0 0"/>
      <geometry>
        <mesh filename="meshes/visual/idx-F2.stl"/>
      </geometry>
      <material name="panda_white"/>
    </visual>
  </link>
  <joint name="ring_q1" type="revolute">
    <parent link="wrist"/>
    <child link="ring_L1"/>
    <origin xyz="29.954260e-3 -14.212492e-3 -67.286105e-3" rpy="-1.716598 1.321452 -1.675862"/>
    <limit lower="0" upper="2.0943951" effort="0.20" velocity="8.0677777442"/>
    <!-- angles in rad, efforts in N-m, velocity in rad/s -->
    <dynamics damping="0.001" friction="0.001"/>
    <!-- Friction coefficient is not from quantitative measurement -->
    <axis xyz="0 0 1"/>
  </joint>
  <joint name="ring_q2" type="revolute">
    <parent link="ring_L1"/>
    <child link="ring_L2"/>
    <origin xyz="38.472723e-3 3.257695e-3 0.000000" rpy="0 0 0.084474"/>
    <axis xyz="0 0 1"/>
    <limit lower="0.0" upper="2.6586" effort="0.20" velocity="8.0677777442"/>
    <!-- angles in rad, efforts in N-m, velocity in rad/s -->
    <dynamics damping="0.001" friction="0.001"/>
    <!-- Friction coefficient is not from quantitative measurement -->
  </joint>
  <link name="pinky_L1">
    <inertial>
      <mass value="0.00635888"/>
      <inertia ixx="0.29766e-6" ixy="-0.06447133e-6" ixz="-0.00423315e-6" iyy="3.6947967e-6" iyz="0.00083028e-6" izz="3.8176336e-6"/>
      <origin xyz="22.41911e-3 -0.15798201e-3 -0.01319866e-3" rpy="0 0 0"/>
    </inertial>
    <visual>
      <origin xyz="0 0 0" rpy="0 0 0"/>
      <geometry>
        <sphere radius="7e-3"/>
      </geometry>
    </visual>
    <visual>
      <origin xyz="19.23500e-3 1.62500e-3 0" rpy="0 0 0.084474"/>
      <geometry>
        <box size="38.6070382e-3 4e-3 4e-3"/>
      </geometry>
    </visual>
    <visual>
      <origin xyz="38.472723e-3 3.257695e-3 0.000000" rpy="0 0 0.084474"/>
      <geometry>
        <mesh filename="meshes/visual/idx-F1.stl"/>
      </geometry>
      <material name="panda_white"/>
    </visual>
  </link>
  <link name="pinky_L2">
    <inertial>
      <mass value="0.00645"/>
      <inertia ixx="0.82671e-6" ixy="-1.08876e-6" ixz="-0.00037e-6" iyy="1.98028e-6" iyz="0.00081e-6" izz="2.64638e-6"/>
      <origin rpy="0 0 0" xyz="13.36818e-3 -8.75392e-3 -0.02886e-3"/>
    </inertial>
    <visual>
      <origin xyz="0 0 0" rpy="0 0 0"/>
      <geometry>
        <sphere radius="5e-3"/>
      </geometry>
    </visual>
    <visual>
      <origin xyz="15.5333e-3 -8.501e-3 0" rpy="0 0 -0.500734962"/>
      <geometry>
        <box size="35.41e-3 4e-3 4e-3"/>
      </geometry>
    </visual>
    <visual>
      <origin xyz="29.159500e-3 -11.643970e-3 -0.148280e-3" rpy="1.5708 0 -0.420107"/>
      <geometry>
        <cylinder length="3e-3" radius="4e-3"/>
      </geometry>
    </visual>
    <visual>
      <origin rpy="0 0 0" xyz="9.1241e-3 0 0"/>
      <geometry>
        <mesh filename="meshes/visual/idx-F2.stl"/>
      </geometry>
      <material name="panda_white"/>
    </visual>
  </link>
  <joint name="pinky_q1" type="revolute">
    <parent link="wrist"/>
    <child link="pinky_L1"/>
    <origin xyz="49.521293e-3 -11.004583e-3 -63.029065e-3" rpy="-1.765110 1.322220 -1.658383"/>
    <limit lower="0" upper="2.0943951" effort="0.20" velocity="8.0677777442"/>
    <!-- angles in rad, efforts in N-m, velocity in rad/s -->
    <dynamics damping="0.001" friction="0.001"/>
    <!-- Friction coefficient is not from quantitative measurement -->
    <axis xyz="0 0 1"/>
  </joint>
  <joint name="pinky_q2" type="revolute">
    <parent link="pinky_L1"/>
    <child link="pinky_L2"/>
    <origin xyz="38.472723e-3 3.257695e-3 0.000000" rpy="0 0 0.084474"/>
    <limit lower="0.0" upper="2.6586" effort="0.20" velocity="8.0677777442"/>
    <!-- angles in rad, efforts in N-m, velocity in rad/s -->
    <dynamics damping="0.001" friction="0.001"/>
    <!-- Friction coefficient is not from quantitative measurement -->
    <axis xyz="0 0 1"/>
  </joint>
  <link name="thumb_L1">
    <inertial>
      <mass value="0.00268342"/>
      <inertia ixx="0.16931e-6" ixy="-0.076214e-6" ixz="-0.16959148e-6" iyy="0.77769934e-6" iyz="0.0156622e-6" izz="0.7249122e-6"/>
      <origin rpy="0 0 0" xyz="14.606e-3 -1.890854e-3 -3.1155356e-3"/>
    </inertial>
    <visual>
      <origin xyz="13.851489e-3 -1.900374e-3 -6.866140e-3" rpy="0.490960 0.456500 -0.136345"/>
      <geometry>
        <box size="31.15246724e-3 5e-3 4e-3"/>
      </geometry>
    </visual>
    <visual>
      <origin xyz="0 0 0" rpy="0 0 0"/>
      <geometry>
        <sphere radius="8e-3"/>
        <!--<cylinder length = "14" radius = "7"/>-->
      </geometry>
    </visual>
    <visual>
      <origin xyz="27.8283501e-3 0 -14.7507000e-3" rpy="4.450589592585541 0 0"/>
      <geometry>
        <mesh filename="meshes/visual/thumb-F1.stl"/>
      </geometry>
      <material name="panda_white"/>
    </visual>
  </link>
  <link name="thumb_L2">
    <inertial>
      <mass value="0.0055"/>
      <inertia ixx="4.4789082e-6" ixy="4.4789082e-6" ixz="-0.62144934e-6" iyy="15.600996e-6" iyz="-0.07466143e-6" izz="17.908554e-6"/>
      <origin rpy="0 0 0" xyz="30.020522e-3 5.59476e-3 -4.1504356e-3"/>
    </inertial>
    <visual>
      <origin xyz="0 0 -3.93482782e-3" rpy="0 0 0"/>
      <!-- rotation axis cylinder -->
      <geometry>
        <sphere radius="8.9e-3"/>
        <!--<cylinder length = "7" radius = "8.9"/>-->
      </geometry>
    </visual>
    <visual>
      <origin xyz="26.851927e-3 6.766622e-3 -3.934828e-3" rpy="0.000000 -0.000000 0.462507"/>
      <geometry>
        <box size="60.93e-3 4e-3 8e-3"/>
      </geometry>
    </visual>
    <visual>
      <origin xyz="56.730453e-3 19.890903e-3 -3.934828e-3" rpy="1.570800 -0.000000 0.343830"/>
      <geometry>
        <cylinder length="7e-3" radius="7e-3"/>
      </geometry>
    </visual>
    <visual>
      <origin xyz="65.18669e-3 23.34021e-3 -3.93483e-3" rpy="3.141592 0 0.343830"/>
      <geometry>
        <mesh filename="meshes/visual/thumb-F2.stl"/>
      </geometry>
      <material name="panda_white"/>
    </visual>
  </link>
  <joint name="thumb_q1" type="revolute">
    <parent link="wrist"/>
    <child link="thumb_L1"/>
    <origin xyz="0 0 0" rpy="0 0 3.330437"/>
    <axis xyz="0 0 1"/>
    <limit lower="-2.0943951" upper="0" effort="0.20" velocity="8.0677777442"/>
    <!-- angles in rad, efforts in N-m, velocity in rad/s -->
    <dynamics damping="0.001" friction="0.001"/>
    <!-- Friction coefficient is not from quantitative measurement -->
  </joint>
  <joint name="thumb_q2" type="revolute">
    <parent link="thumb_L1"/>
    <child link="thumb_L2"/>
    <origin xyz="27.8283501e-3 0 -14.7507000e-3" rpy="4.450589592585541 0 0"/>
    <axis xyz="0 0 1"/>
    <limit lower="0" upper="2.0943951" effort="0.20" velocity="8.0677777442"/>
    <!-- angles in rad, efforts in N-m, velocity in rad/s -->
    <dynamics damping="0.001" friction="0.001"/>
    <!-- Friction coefficient is not from quantitative measurement -->
  </joint>
</robot>
